<?xml version="1.0"?>
<sdf version="1.6">
  <model name="hillstar">
    <link name="quad_plate_arm_subassembly">



      <sensor name="air_pressure_sensor" type="air_pressure">
        <always_on>1</always_on>
        <update_rate>50</update_rate>
        <air_pressure>
          <pressure>
            <noise type="gaussian">
              <mean>0</mean>
              <stddev>0.01</stddev>
            </noise>
          </pressure>
        </air_pressure>
      </sensor>
      <sensor name="imu_sensor" type="imu">
        <parent>quad_plate_arm_subassembly</parent>
        <always_on>1</always_on>
        <update_rate>250</update_rate>
        <imu>
          <angular_velocity>
            <x>
              <noise type="gaussian">
                <mean>0</mean>
                <stddev>0.00018665</stddev>
                <dynamic_bias_stddev>3.8785e-05</dynamic_bias_stddev>
                <dynamic_bias_correlation_time>1000</dynamic_bias_correlation_time>
              </noise>
            </x>
            <y>
              <noise type="gaussian">
                <mean>0</mean>
                <stddev>0.00018665</stddev>
                <dynamic_bias_stddev>3.8785e-05</dynamic_bias_stddev>
                <dynamic_bias_correlation_time>1000</dynamic_bias_correlation_time>
              </noise>
            </y>
            <z>
              <noise type="gaussian">
                <mean>0</mean>
                <stddev>0.00018665</stddev>
                <dynamic_bias_stddev>3.8785e-05</dynamic_bias_stddev>
                <dynamic_bias_correlation_time>1000</dynamic_bias_correlation_time>
              </noise>
            </z>
          </angular_velocity>
          <linear_acceleration>
            <x>
              <noise type="gaussian">
                <mean>0</mean>
                <stddev>0.00186</stddev>
                <dynamic_bias_stddev>0.006</dynamic_bias_stddev>
                <dynamic_bias_correlation_time>300</dynamic_bias_correlation_time>
              </noise>
            </x>
            <y>
              <noise type="gaussian">
                <mean>0</mean>
                <stddev>0.00186</stddev>
                <dynamic_bias_stddev>0.006</dynamic_bias_stddev>
                <dynamic_bias_correlation_time>300</dynamic_bias_correlation_time>
              </noise>
            </y>
            <z>
              <noise type="gaussian">
                <mean>0</mean>
                <stddev>0.00186</stddev>
                <dynamic_bias_stddev>0.006</dynamic_bias_stddev>
                <dynamic_bias_correlation_time>300</dynamic_bias_correlation_time>
              </noise>
            </z>
          </linear_acceleration>
        </imu>
        <plugin name="px4_gazebo_imu_plugin" filename="libgazebo_imu_plugin.so">
          <imu_name>"imu_sensor"</imu_name> 
        </plugin> 
      </sensor>
      <sensor name="navsat_sensor" type="navsat">
        <parent>quad_plate_arm_subassembly</parent>
        <always_on>1</always_on>
        <update_rate>30</update_rate>
      </sensor>

      <frame name="quad_plate_arm_subassembly_frame">
        <pose>0 0 0 0 -0 0</pose>
      </frame>
      <visual name="quad_plate_arm_subassembly_0_electronics_tray_visual">
        <pose>1.0426410892068930198e-17 1.686536712755228713e-18 -0.010000000000000000208 -1.570796326794896558 2.426671729927918817e-32 -5.8286708792820738094e-16</pose>
        <geometry>
          <mesh>
            <uri>model://hillstar/quad_layout_sdf//electronics_tray.stl</uri>
          </mesh>
        </geometry>
        <material>
          <ambient>0.61568627450980395466 0.81176470588235294379 0.92941176470588238168 1</ambient>
          <diffuse>0.61568627450980395466 0.81176470588235294379 0.92941176470588238168 1</diffuse>
          <specular>0.1 0.1 0.1 1</specular>
          <emissive>0 0 0 0</emissive>
        </material>
      </visual>
      <collision name="quad_plate_arm_subassembly_0_electronics_tray_visual">
        <pose>1.0426410892068930198e-17 1.686536712755228713e-18 -0.010000000000000000208 -1.570796326794896558 2.426671729927918817e-32 -5.8286708792820738094e-16</pose>
        <geometry>
          <mesh>
            <uri>model://hillstar/quad_layout_sdf//electronics_tray.stl</uri>
          </mesh>
        </geometry>
      </collision>



      <visual name="quad_plate_arm_subassembly_1_legs_visual">
        <pose>-2.5459897982298789269e-18 -0.0025000000000000052562 -0.035999999999999927891 1.9428902930940261644e-16 1.7809827686695217859e-16 3.1415926535897926719</pose>
        <geometry>
          <mesh>
            <uri>model://hillstar/quad_layout_sdf//legs.stl</uri>
          </mesh>
        </geometry>
        <material>
          <ambient>0.61568627450980395466 0.81176470588235294379 0.92941176470588238168 1</ambient>
          <diffuse>0.61568627450980395466 0.81176470588235294379 0.92941176470588238168 1</diffuse>
          <specular>0.1 0.1 0.1 1</specular>
          <emissive>0 0 0 0</emissive>
        </material>
      </visual>
      <collision name="quad_plate_arm_subassembly_1_legs_visual">
        <pose>-2.5459897982298789269e-18 -0.0025000000000000052562 -0.035999999999999927891 1.9428902930940261644e-16 1.7809827686695217859e-16 3.1415926535897926719</pose>
        <geometry>
          <mesh>
            <uri>model://hillstar/quad_layout_sdf//legs.stl</uri>
          </mesh>
        </geometry>
      </collision>
      <visual name="quad_plate_arm_subassembly_2_center_plate_visual">
        <pose>-4.429638872090642462e-33 -4.6510602907817071607e-18 -0.010000000000000000208 1.5707963267948990005 -1.1102230246251548148e-16 3.1415926535897926719</pose>
        <geometry>
          <mesh>
            <uri>model://hillstar/quad_layout_sdf//center_plate.stl</uri>
          </mesh>
        </geometry>
        <material>
          <ambient>0.61568627450980395466 0.81176470588235294379 0.92941176470588238168 1</ambient>
          <diffuse>0.61568627450980395466 0.81176470588235294379 0.92941176470588238168 1</diffuse>
          <specular>0.1 0.1 0.1 1</specular>
          <emissive>0 0 0 0</emissive>
        </material>
      </visual>
      <collision name="quad_plate_arm_subassembly_2_center_plate_visual">
        <pose>-4.429638872090642462e-33 -4.6510602907817071607e-18 -0.010000000000000000208 1.5707963267948990005 -1.1102230246251548148e-16 3.1415926535897926719</pose>
        <geometry>
          <mesh>
            <uri>model://hillstar/quad_layout_sdf//center_plate.stl</uri>
          </mesh>
        </geometry>
      </collision>
      <visual name="quad_plate_arm_subassembly_3_arm_tube_visual">
        <pose>0.26369959271719034533 -1.3152048885202173023e-16 0.0057470236776120389374 3.0019663134302465579 2.3592239273284548874e-15 1.570796326794896558</pose>
        <geometry>
          <mesh>
            <uri>model://hillstar/quad_layout_sdf//arm_tube.stl</uri>
          </mesh>
        </geometry>
        <material>
          <ambient>0.61568627450980395466 0.81176470588235294379 0.92941176470588238168 1</ambient>
          <diffuse>0.61568627450980395466 0.81176470588235294379 0.92941176470588238168 1</diffuse>
          <specular>0.1 0.1 0.1 1</specular>
          <emissive>0 0 0 0</emissive>
        </material>
      </visual>
      <collision name="quad_plate_arm_subassembly_3_arm_tube_visual">
        <pose>0.26369959271719034533 -1.3152048885202173023e-16 0.0057470236776120389374 3.0019663134302465579 2.3592239273284548874e-15 1.570796326794896558</pose>
        <geometry>
          <mesh>
            <uri>model://hillstar/quad_layout_sdf//arm_tube.stl</uri>
          </mesh>
        </geometry>
      </collision>
      <visual name="quad_plate_arm_subassembly_4_arm_tube_visual">
        <pose>9.2729227200666873604e-17 0.26369959271719034533 0.0057470236776120458763 3.0019663134302474461 -1.6081226496766373401e-16 3.1415926535897926719</pose>
        <geometry>
          <mesh>
            <uri>model://hillstar/quad_layout_sdf//arm_tube.stl</uri>
          </mesh>
        </geometry>
        <material>
          <ambient>0.61568627450980395466 0.81176470588235294379 0.92941176470588238168 1</ambient>
          <diffuse>0.61568627450980395466 0.81176470588235294379 0.92941176470588238168 1</diffuse>
          <specular>0.1 0.1 0.1 1</specular>
          <emissive>0 0 0 0</emissive>
        </material>
      </visual>
      <collision name="quad_plate_arm_subassembly_4_arm_tube_visual">
        <pose>9.2729227200666873604e-17 0.26369959271719034533 0.0057470236776120458763 3.0019663134302474461 -1.6081226496766373401e-16 3.1415926535897926719</pose>
        <geometry>
          <mesh>
            <uri>model://hillstar/quad_layout_sdf//arm_tube.stl</uri>
          </mesh>
        </geometry>
      </collision>
      <visual name="quad_plate_arm_subassembly_5_arm_tube_visual">
        <pose>-1.125288682431912656e-16 -0.26369959271719034533 0.0057470236776121490924 3.0019663134302465579 2.8327694488239903007e-16 -5.8513504420383324006e-16</pose>
        <geometry>
          <mesh>
            <uri>model://hillstar/quad_layout_sdf//arm_tube.stl</uri>
          </mesh>
        </geometry>
        <material>
          <ambient>0.61568627450980395466 0.81176470588235294379 0.92941176470588238168 1</ambient>
          <diffuse>0.61568627450980395466 0.81176470588235294379 0.92941176470588238168 1</diffuse>
          <specular>0.1 0.1 0.1 1</specular>
          <emissive>0 0 0 0</emissive>
        </material>
      </visual>
      <collision name="quad_plate_arm_subassembly_5_arm_tube_visual">
        <pose>-1.125288682431912656e-16 -0.26369959271719034533 0.0057470236776121490924 3.0019663134302465579 2.8327694488239903007e-16 -5.8513504420383324006e-16</pose>
        <geometry>
          <mesh>
            <uri>model://hillstar/quad_layout_sdf//arm_tube.stl</uri>
          </mesh>
        </geometry>
      </collision>
      <visual name="quad_plate_arm_subassembly_6_arm_tube_visual">
        <pose>-0.26369959271719034533 1.2880560503267202442e-16 0.0057470236776121560313 3.0019663134302465579 -1.3305668935203479585e-16 -1.5707963267948972241</pose>
        <geometry>
          <mesh>
            <uri>model://hillstar/quad_layout_sdf//arm_tube.stl</uri>
          </mesh>
        </geometry>
        <material>
          <ambient>0.61568627450980395466 0.81176470588235294379 0.92941176470588238168 1</ambient>
          <diffuse>0.61568627450980395466 0.81176470588235294379 0.92941176470588238168 1</diffuse>
          <specular>0.1 0.1 0.1 1</specular>
          <emissive>0 0 0 0</emissive>
        </material>
      </visual>
      <collision name="quad_plate_arm_subassembly_6_arm_tube_visual">
        <pose>-0.26369959271719034533 1.2880560503267202442e-16 0.0057470236776121560313 3.0019663134302465579 -1.3305668935203479585e-16 -1.5707963267948972241</pose>
        <geometry>
          <mesh>
            <uri>model://hillstar/quad_layout_sdf//arm_tube.stl</uri>
          </mesh>
        </geometry>
      </collision>
      <inertial>
        <pose frame="quad_plate_arm_subassembly_frame">-6.1462580748651722459e-07 -0.00017942040463946536707 -0.029584627107929153955 0 0 0</pose>
        <mass>0.77207657554993003313</mass>
        <inertia>
          <ixx>0.0031604844513892912591</ixx>
          <ixy>-3.8238647302225609731e-08</ixy>
          <ixz>1.0003578610147444237e-08</ixz>
          <iyy>0.0033332661413842785102</iyy>
          <iyz>-1.7931547486300860873e-05</iyz>
          <izz>0.0043410841365872331055</izz>
        </inertia>
      </inertial>
    </link>
    <link name="motor_subassembly">
      <frame name="motor_subassembly_frame">
        <pose>0 0 0 0 -0 0</pose>
      </frame>
      <visual name="motor_subassembly_0_mount_tube_visual">
        <pose>8.8211977744013656535e-17 0.26369959271719034533 0.0057470236776120311312 -0.13962634015954397682 6.4392935428257951273e-15 -3.1415926535897908956</pose>
        <geometry>
          <mesh>
            <uri>model://hillstar/quad_layout_sdf//mount_tube.stl</uri>
          </mesh>
        </geometry>
        <material>
          <ambient>0.61568627450980395466 0.81176470588235294379 0.92941176470588238168 1</ambient>
          <diffuse>0.61568627450980395466 0.81176470588235294379 0.92941176470588238168 1</diffuse>
          <specular>0.1 0.1 0.1 1</specular>
          <emissive>0 0 0 0</emissive>
        </material>
      </visual>
      <collision name="motor_subassembly_0_mount_tube_visual">
        <pose>8.8211977744013656535e-17 0.26369959271719034533 0.0057470236776120311312 -0.13962634015954397682 6.4392935428257951273e-15 -3.1415926535897908956</pose>
        <geometry>
          <mesh>
            <uri>model://hillstar/quad_layout_sdf//mount_tube.stl</uri>
          </mesh>
        </geometry>
      </collision>
      <visual name="motor_subassembly_1_motor_visual">
        <pose>1.4500233842945824097e-16 0.28873464063764958665 0.007245815064130314842 -0.13962634015955874278 -1.3771378040183450102e-14 -3.1415926535897860106</pose>
        <geometry>
          <mesh>
            <uri>model://hillstar/quad_layout_sdf//motor.stl</uri>
          </mesh>
        </geometry>
        <material>
          <ambient>0.91764705882352937127 0.91764705882352937127 0.91764705882352937127 1</ambient>
          <diffuse>0.91764705882352937127 0.91764705882352937127 0.91764705882352937127 1</diffuse>
          <specular>0.1 0.1 0.1 1</specular>
          <emissive>0 0 0 0</emissive>
        </material>
      </visual>
      <collision name="motor_subassembly_1_motor_visual">
        <pose>1.4500233842945824097e-16 0.28873464063764958665 0.007245815064130314842 -0.13962634015955874278 -1.3771378040183450102e-14 -3.1415926535897860106</pose>
        <geometry>
          <mesh>
            <uri>model://hillstar/quad_layout_sdf//motor.stl</uri>
          </mesh>
        </geometry>
      </collision>
      <visual name="motor_subassembly_2_mount_bottom_visual">
        <pose>9.2128612509324812694e-17 0.2884562944357294545 0.0092263512016136396687 -0.13962634015954550337 2.0539125955566808059e-15 -3.141592653589788231</pose>
        <geometry>
          <mesh>
            <uri>model://hillstar/quad_layout_sdf//mount_bottom.stl</uri>
          </mesh>
        </geometry>
        <material>
          <ambient>0.2313725490196078538 0.38039215686274507888 0.7058823529411765163 1</ambient>
          <diffuse>0.2313725490196078538 0.38039215686274507888 0.7058823529411765163 1</diffuse>
          <specular>0.1 0.1 0.1 1</specular>
          <emissive>0 0 0 0</emissive>
        </material>
      </visual>
      <collision name="motor_subassembly_2_mount_bottom_visual">
        <pose>9.2128612509324812694e-17 0.2884562944357294545 0.0092263512016136396687 -0.13962634015954550337 2.0539125955566808059e-15 -3.141592653589788231</pose>
        <geometry>
          <mesh>
            <uri>model://hillstar/quad_layout_sdf//mount_bottom.stl</uri>
          </mesh>
        </geometry>
      </collision>
      <visual name="motor_subassembly_3_mount_top_visual">
        <pose>1.1281518996034820771e-16 0.28845629443572939898 0.0092263512016136223215 -0.13962634015954725197 2.0539125955565656322e-15 -3.141592653589788231</pose>
        <geometry>
          <mesh>
            <uri>model://hillstar/quad_layout_sdf//mount_top.stl</uri>
          </mesh>
        </geometry>
        <material>
          <ambient>0.64705882352941179736 0.64705882352941179736 0.64705882352941179736 1</ambient>
          <diffuse>0.64705882352941179736 0.64705882352941179736 0.64705882352941179736 1</diffuse>
          <specular>0.1 0.1 0.1 1</specular>
          <emissive>0 0 0 0</emissive>
        </material>
      </visual>
      <collision name="motor_subassembly_3_mount_top_visual">
        <pose>1.1281518996034820771e-16 0.28845629443572939898 0.0092263512016136223215 -0.13962634015954725197 2.0539125955565656322e-15 -3.141592653589788231</pose>
        <geometry>
          <mesh>
            <uri>model://hillstar/quad_layout_sdf//mount_top.stl</uri>
          </mesh>
        </geometry>
      </collision>
      <inertial>
        <pose frame="motor_subassembly_frame">1.8015628869976593456e-16 0.29810053067448233355 0.01575118727399961796 0 0 0</pose>
        <mass>0.11166174231785991333</mass>
        <inertia>
          <ixx>2.0082952529287045803e-05</ixx>
          <ixy>1.1612149890983393133e-21</ixy>
          <ixz>7.1314863429422230699e-20</ixz>
          <iyy>1.614878726894681285e-05</iyy>
          <iyz>-1.1832065003416649547e-06</iyz>
          <izz>1.5934066887227138124e-05</izz>
        </inertia>
      </inertial>
    </link>
    <link name="prop">
      <frame name="prop_frame">
        <pose>0 0 0 0 -0 0</pose>
      </frame>
      <visual name="prop_0_prop_visual">
        <pose>5.0951498899341699441e-16 0.29707697156907691971 0.037703252819636781656 -1.57079632679479686 1.4311699866353377875 1.5707963267950026953</pose>
        <geometry>
          <mesh>
            <uri>model://hillstar/quad_layout_sdf//prop.stl</uri>
          </mesh>
        </geometry>
        <material>
          <ambient>0.61568627450980395466 0.81176470588235294379 0.92941176470588238168 1</ambient>
          <diffuse>0.61568627450980395466 0.81176470588235294379 0.92941176470588238168 1</diffuse>
          <specular>0.1 0.1 0.1 1</specular>
          <emissive>0 0 0 0</emissive>
        </material>
      </visual>
      <collision name="prop_0_prop_visual">
        <pose>5.0951498899341699441e-16 0.29707697156907691971 0.037703252819636781656 -1.57079632679479686 1.4311699866353377875 1.5707963267950026953</pose>
        <geometry>
          <mesh>
            <uri>model://hillstar/quad_layout_sdf//prop.stl</uri>
          </mesh>
        </geometry>
      </collision>
      <inertial>
        <pose frame="prop_frame">4.851341770526906169e-16 0.29728573122051704658 0.036217850716524425947 0 0 0</pose>
        <mass>0.024723492811985364054</mass>
        <inertia>
          <ixx>0.00022462477770931595588</ixx>
          <ixy>1.167288566972933816e-18</ixy>
          <ixz>1.7610046249642690061e-19</ixz>
          <iyy>5.1936008690255026807e-06</iyy>
          <iyz>-3.0952378850752287692e-05</iyz>
          <izz>0.00022108114701970384489</izz>
        </inertia>
      </inertial>
    </link>
    <joint name="rotor0" type="revolute">
      <pose>5.094231404834809462e-16 0.29707697156907691971 0.037703252819636781656 -1.4021364536729796336e-14 0.13962634015955888156 -1.5707963267948912289</pose>
      <parent>motor_subassembly</parent>
      <child>prop</child>
      <axis>
        <xyz>0 0 1</xyz>
        <limit>
          <effort>1</effort>
          <velocity>20</velocity>
        </limit>
      </axis>
    </joint>
    <joint name="tilt0" type="revolute">
      <pose>8.8211977744013656535e-17 0.26369959271719034533 0.0057470236776120311312 -1.7104226669544406736 6.4392935428257951273e-15 -3.1415926535897908956</pose>
      <parent>quad_plate_arm_subassembly</parent>
      <child>motor_subassembly</child>
      <axis>
        <xyz>0 0 1</xyz>
        <limit>
          <effort>1</effort>
          <velocity>20</velocity>
        </limit>
      </axis>
    </joint>
    <link name="motor_subassembly_2">
      <frame name="motor_subassembly_2_frame">
        <pose>0 0 0 0 -0 0</pose>
      </frame>
      <visual name="motor_subassembly_2_0_mount_tube_visual">
        <pose>-1.0693581973587520044e-16 -0.26369959271719028981 0.0057470236776121369493 -0.13962634015954608624 1.4988010832439605407e-15 -2.8167572441173419987e-16</pose>
        <geometry>
          <mesh>
            <uri>model://hillstar/quad_layout_sdf//mount_tube.stl</uri>
          </mesh>
        </geometry>
        <material>
          <ambient>0.61568627450980395466 0.81176470588235294379 0.92941176470588238168 1</ambient>
          <diffuse>0.61568627450980395466 0.81176470588235294379 0.92941176470588238168 1</diffuse>
          <specular>0.1 0.1 0.1 1</specular>
          <emissive>0 0 0 0</emissive>
        </material>
      </visual>
      <collision name="motor_subassembly_2_0_mount_tube_visual">
        <pose>-1.0693581973587520044e-16 -0.26369959271719028981 0.0057470236776121369493 -0.13962634015954608624 1.4988010832439605407e-15 -2.8167572441173419987e-16</pose>
        <geometry>
          <mesh>
            <uri>model://hillstar/quad_layout_sdf//mount_tube.stl</uri>
          </mesh>
        </geometry>
      </collision>
      <visual name="motor_subassembly_2_1_motor_visual">
        <pose>-1.8150222223602479181e-16 -0.28873464063764975318 0.007245815064130293158 -0.13962634015954358824 2.2204460492503840783e-16 -1.8912605856402206795e-14</pose>
        <geometry>
          <mesh>
            <uri>model://hillstar/quad_layout_sdf//motor.stl</uri>
          </mesh>
        </geometry>
        <material>
          <ambient>0.91764705882352937127 0.91764705882352937127 0.91764705882352937127 1</ambient>
          <diffuse>0.91764705882352937127 0.91764705882352937127 0.91764705882352937127 1</diffuse>
          <specular>0.1 0.1 0.1 1</specular>
          <emissive>0 0 0 0</emissive>
        </material>
      </visual>
      <collision name="motor_subassembly_2_1_motor_visual">
        <pose>-1.8150222223602479181e-16 -0.28873464063764975318 0.007245815064130293158 -0.13962634015954358824 2.2204460492503840783e-16 -1.8912605856402206795e-14</pose>
        <geometry>
          <mesh>
            <uri>model://hillstar/quad_layout_sdf//motor.stl</uri>
          </mesh>
        </geometry>
      </collision>
      <visual name="motor_subassembly_2_2_mount_bottom_visual">
        <pose>-1.093039201947344613e-16 -0.28845629443572984307 0.0092263512016138062022 -0.13962634015954353273 5.5511151231257767857e-16 -1.8968117007633862208e-14</pose>
        <geometry>
          <mesh>
            <uri>model://hillstar/quad_layout_sdf//mount_bottom.stl</uri>
          </mesh>
        </geometry>
        <material>
          <ambient>0.2313725490196078538 0.38039215686274507888 0.7058823529411765163 1</ambient>
          <diffuse>0.2313725490196078538 0.38039215686274507888 0.7058823529411765163 1</diffuse>
          <specular>0.1 0.1 0.1 1</specular>
          <emissive>0 0 0 0</emissive>
        </material>
      </visual>
      <collision name="motor_subassembly_2_2_mount_bottom_visual">
        <pose>-1.093039201947344613e-16 -0.28845629443572984307 0.0092263512016138062022 -0.13962634015954353273 5.5511151231257767857e-16 -1.8968117007633862208e-14</pose>
        <geometry>
          <mesh>
            <uri>model://hillstar/quad_layout_sdf//mount_bottom.stl</uri>
          </mesh>
        </geometry>
      </collision>
      <visual name="motor_subassembly_2_3_mount_top_visual">
        <pose>-1.1485503531786022428e-16 -0.28845629443572962103 0.009226351201613719466 -0.1396263401595466136 -4.4408920985006478554e-16 -1.8787705766132334223e-14</pose>
        <geometry>
          <mesh>
            <uri>model://hillstar/quad_layout_sdf//mount_top.stl</uri>
          </mesh>
        </geometry>
        <material>
          <ambient>0.64705882352941179736 0.64705882352941179736 0.64705882352941179736 1</ambient>
          <diffuse>0.64705882352941179736 0.64705882352941179736 0.64705882352941179736 1</diffuse>
          <specular>0.1 0.1 0.1 1</specular>
          <emissive>0 0 0 0</emissive>
        </material>
      </visual>
      <collision name="motor_subassembly_2_3_mount_top_visual">
        <pose>-1.1485503531786022428e-16 -0.28845629443572962103 0.009226351201613719466 -0.1396263401595466136 -4.4408920985006478554e-16 -1.8787705766132334223e-14</pose>
        <geometry>
          <mesh>
            <uri>model://hillstar/quad_layout_sdf//mount_top.stl</uri>
          </mesh>
        </geometry>
      </collision>
      <inertial>
        <pose frame="motor_subassembly_2_frame">-1.1755050186215506707e-16 -0.29810053067448250008 0.015751187273999912863 0 0 0</pose>
        <mass>0.11166174231785991333</mass>
        <inertia>
          <ixx>2.0082952529287509977e-05</ixx>
          <ixy>-9.7453422952255673381e-20</ixy>
          <ixz>1.3191310848233248902e-20</ixz>
          <iyy>1.6148787268947094065e-05</iyy>
          <iyz>1.1832065003416137092e-06</iyz>
          <izz>1.5934066887227483713e-05</izz>
        </inertia>
      </inertial>
    </link>
    <link name="prop_2">
      <frame name="prop_2_frame">
        <pose>0 0 0 0 -0 0</pose>
      </frame>
      <visual name="prop_2_0_prop_visual">
        <pose>-1.0810466104008906351e-16 -0.29707697156907741931 0.037703252819637787796 -1.5707963267949045516 1.4311699866353515542 -1.5707963267948961139</pose>
        <geometry>
          <mesh>
            <uri>model://hillstar/quad_layout_sdf//prop.stl</uri>
          </mesh>
        </geometry>
        <material>
          <ambient>0.61568627450980395466 0.81176470588235294379 0.92941176470588238168 1</ambient>
          <diffuse>0.61568627450980395466 0.81176470588235294379 0.92941176470588238168 1</diffuse>
          <specular>0.1 0.1 0.1 1</specular>
          <emissive>0 0 0 0</emissive>
        </material>
      </visual>
      <collision name="prop_2_0_prop_visual">
        <pose>-1.0810466104008906351e-16 -0.29707697156907741931 0.037703252819637787796 -1.5707963267949045516 1.4311699866353515542 -1.5707963267948961139</pose>
        <geometry>
          <mesh>
            <uri>model://hillstar/quad_layout_sdf//prop.stl</uri>
          </mesh>
        </geometry>
      </collision>
      <inertial>
        <pose frame="prop_2_frame">-1.057756882154955986e-16 -0.29728573122051754618 0.036217850716525369636 0 0 0</pose>
        <mass>0.024723492811985364054</mass>
        <inertia>
          <ixx>0.00022462477770932734</ixx>
          <ixy>-4.0922419324439419315e-18</ixy>
          <ixz>-2.6276671836410515555e-19</ixz>
          <iyy>5.1936008690250063194e-06</iyy>
          <iyz>3.0952378850751806577e-05</iyz>
          <izz>0.00022108114701972243895</izz>
        </inertia>
      </inertial>
    </link>
    <joint name="rotor1" type="revolute">
      <pose>-1.080128125301530153e-16 -0.29707697156907741931 0.037703252819637787796 1.1211338219114685851e-15 0.13962634015954783484 1.5707963267948996666</pose>
      <parent>motor_subassembly_2</parent>
      <child>prop_2</child>
      <axis>
        <xyz>0 0 1</xyz>
        <limit>
          <effort>1</effort>
          <velocity>20</velocity>
        </limit>
      </axis>
    </joint>
    <joint name="tilt1" type="revolute">
      <pose>-1.0693581973587520044e-16 -0.26369959271719028981 0.0057470236776121369493 -1.710422666954442672 1.4988010832439605407e-15 -2.8167572441173419987e-16</pose>
      <parent>quad_plate_arm_subassembly</parent>
      <child>motor_subassembly_2</child>
      <axis>
        <xyz>0 0 1</xyz>
        <limit>
          <effort>1</effort>
          <velocity>20</velocity>
        </limit>
      </axis>
    </joint>
    <link name="motor_subassembly_3">
      <frame name="motor_subassembly_3_frame">
        <pose>0 0 0 0 -0 0</pose>
      </frame>
      <visual name="motor_subassembly_3_0_mount_tube_visual">
        <pose>-0.26369959271719028981 1.1722743512342384814e-16 0.0057470236776121803174 -0.13962634015954744626 1.0269562977782692082e-15 -1.570796326794896558</pose>
        <geometry>
          <mesh>
            <uri>model://hillstar/quad_layout_sdf//mount_tube.stl</uri>
          </mesh>
        </geometry>
        <material>
          <ambient>0.61568627450980395466 0.81176470588235294379 0.92941176470588238168 1</ambient>
          <diffuse>0.61568627450980395466 0.81176470588235294379 0.92941176470588238168 1</diffuse>
          <specular>0.1 0.1 0.1 1</specular>
          <emissive>0 0 0 0</emissive>
        </material>
      </visual>
      <collision name="motor_subassembly_3_0_mount_tube_visual">
        <pose>-0.26369959271719028981 1.1722743512342384814e-16 0.0057470236776121803174 -0.13962634015954744626 1.0269562977782692082e-15 -1.570796326794896558</pose>
        <geometry>
          <mesh>
            <uri>model://hillstar/quad_layout_sdf//mount_tube.stl</uri>
          </mesh>
        </geometry>
      </collision>
      <visual name="motor_subassembly_3_1_motor_visual">
        <pose>-0.28873464063764964216 -8.3989372298563775837e-17 0.0072458150641306739298 -0.13962634015953950817 1.915134717478368211e-15 -1.57079632679489678</pose>
        <geometry>
          <mesh>
            <uri>model://hillstar/quad_layout_sdf//motor.stl</uri>
          </mesh>
        </geometry>
        <material>
          <ambient>0.91764705882352937127 0.91764705882352937127 0.91764705882352937127 1</ambient>
          <diffuse>0.91764705882352937127 0.91764705882352937127 0.91764705882352937127 1</diffuse>
          <specular>0.1 0.1 0.1 1</specular>
          <emissive>0 0 0 0</emissive>
        </material>
      </visual>
      <collision name="motor_subassembly_3_1_motor_visual">
        <pose>-0.28873464063764964216 -8.3989372298563775837e-17 0.0072458150641306739298 -0.13962634015953950817 1.915134717478368211e-15 -1.57079632679489678</pose>
        <geometry>
          <mesh>
            <uri>model://hillstar/quad_layout_sdf//motor.stl</uri>
          </mesh>
        </geometry>
      </collision>
      <visual name="motor_subassembly_3_2_mount_bottom_visual">
        <pose>-0.28845629443572934347 1.0794518835740679196e-16 0.0092263512016138131411 -0.13962634015954672462 1.7488713791385803642e-15 -1.57079632679489678</pose>
        <geometry>
          <mesh>
            <uri>model://hillstar/quad_layout_sdf//mount_bottom.stl</uri>
          </mesh>
        </geometry>
        <material>
          <ambient>0.2313725490196078538 0.38039215686274507888 0.7058823529411765163 1</ambient>
          <diffuse>0.2313725490196078538 0.38039215686274507888 0.7058823529411765163 1</diffuse>
          <specular>0.1 0.1 0.1 1</specular>
          <emissive>0 0 0 0</emissive>
        </material>
      </visual>
      <collision name="motor_subassembly_3_2_mount_bottom_visual">
        <pose>-0.28845629443572934347 1.0794518835740679196e-16 0.0092263512016138131411 -0.13962634015954672462 1.7488713791385803642e-15 -1.57079632679489678</pose>
        <geometry>
          <mesh>
            <uri>model://hillstar/quad_layout_sdf//mount_bottom.stl</uri>
          </mesh>
        </geometry>
      </collision>
      <visual name="motor_subassembly_3_3_mount_top_visual">
        <pose>-0.2884562944357294545 -1.2010940006389342202e-17 0.009226351201613951919 -0.13962634015954095146 1.9151347174783678165e-15 -1.57079632679489678</pose>
        <geometry>
          <mesh>
            <uri>model://hillstar/quad_layout_sdf//mount_top.stl</uri>
          </mesh>
        </geometry>
        <material>
          <ambient>0.64705882352941179736 0.64705882352941179736 0.64705882352941179736 1</ambient>
          <diffuse>0.64705882352941179736 0.64705882352941179736 0.64705882352941179736 1</diffuse>
          <specular>0.1 0.1 0.1 1</specular>
          <emissive>0 0 0 0</emissive>
        </material>
      </visual>
      <collision name="motor_subassembly_3_3_mount_top_visual">
        <pose>-0.2884562944357294545 -1.2010940006389342202e-17 0.009226351201613951919 -0.13962634015954095146 1.9151347174783678165e-15 -1.57079632679489678</pose>
        <geometry>
          <mesh>
            <uri>model://hillstar/quad_layout_sdf//mount_top.stl</uri>
          </mesh>
        </geometry>
      </collision>
      <inertial>
        <pose frame="motor_subassembly_3_frame">-0.29810053067448250008 4.4761925134790367899e-17 0.015751187274000016947 0 0 0</pose>
        <mass>0.11166174231785991333</mass>
        <inertia>
          <ixx>1.6148787268947334623e-05</ixx>
          <ixy>-4.557099701407576892e-21</ixy>
          <ixz>1.1832065003416776602e-06</ixz>
          <iyy>2.0082952529287618397e-05</iyy>
          <iyz>5.5346169655793607426e-20</iyz>
          <izz>1.5934066887227446444e-05</izz>
        </inertia>
      </inertial>
    </link>
    <link name="prop_3">
      <frame name="prop_3_frame">
        <pose>0 0 0 0 -0 0</pose>
      </frame>
      <visual name="prop_3_0_prop_visual">
        <pose>-0.29707697156907764136 7.544859064336197574e-17 0.037703252819637815552 -1.5707963267949098807 1.4311699866353593258 -3.1415926535897527039</pose>
        <geometry>
          <mesh>
            <uri>model://hillstar/quad_layout_sdf//prop.stl</uri>
          </mesh>
        </geometry>
        <material>
          <ambient>0.61568627450980395466 0.81176470588235294379 0.92941176470588238168 1</ambient>
          <diffuse>0.61568627450980395466 0.81176470588235294379 0.92941176470588238168 1</diffuse>
          <specular>0.1 0.1 0.1 1</specular>
          <emissive>0 0 0 0</emissive>
        </material>
      </visual>
      <collision name="prop_3_0_prop_visual">
        <pose>-0.29707697156907764136 7.544859064336197574e-17 0.037703252819637815552 -1.5707963267949098807 1.4311699866353593258 -3.1415926535897527039</pose>
        <geometry>
          <mesh>
            <uri>model://hillstar/quad_layout_sdf//prop.stl</uri>
          </mesh>
        </geometry>
      </collision>
      <inertial>
        <pose frame="prop_3_frame">-0.29728573122051771271 6.4743100522619784518e-17 0.036217850716525418209 0 0 0</pose>
        <mass>0.024723492811985364054</mass>
        <inertia>
          <ixx>5.1936008690244150904e-06</ixx>
          <ixy>2.1384046967785722349e-19</ixy>
          <ixz>3.0952378850749306136e-05</ixz>
          <iyy>0.00022462477770932983367</iyy>
          <iyz>1.6749649067333604467e-18</iyz>
          <izz>0.00022108114701971726189</izz>
        </inertia>
      </inertial>
    </link>
    <joint name="rotor2" type="revolute">
      <pose>-0.29707697156907764136 7.5356742133425927534e-17 0.037703252819637815552 1.8641085939145440481e-15 0.13962634015954203393 5.9636439796763860671e-16</pose>
      <parent>motor_subassembly_3</parent>
      <child>prop_3</child>
      <axis>
        <xyz>0 0 1</xyz>
        <limit>
          <effort>1</effort>
          <velocity>20</velocity>
        </limit>
      </axis>
    </joint>
    <joint name="tilt2" type="revolute">
      <pose>-0.26369959271719028981 1.1722743512342384814e-16 0.0057470236776121803174 -1.7104226669544440043 1.0269562977782692082e-15 -1.570796326794896558</pose>
      <parent>quad_plate_arm_subassembly</parent>
      <child>motor_subassembly_3</child>
      <axis>
        <xyz>0 0 1</xyz>
        <limit>
          <effort>1</effort>
          <velocity>20</velocity>
        </limit>
      </axis>
    </joint>
    <link name="motor_subassembly_4">
      <frame name="motor_subassembly_4_frame">
        <pose>0 0 0 0 -0 0</pose>
      </frame>
      <visual name="motor_subassembly_4_0_mount_tube_visual">
        <pose>0.26369959271719034533 -1.1621318268766980023e-16 0.0057470236776120337333 -0.13962634015954558664 1.9151347174783686054e-15 1.5707963267948932273</pose>
        <geometry>
          <mesh>
            <uri>model://hillstar/quad_layout_sdf//mount_tube.stl</uri>
          </mesh>
        </geometry>
        <material>
          <ambient>0.61568627450980395466 0.81176470588235294379 0.92941176470588238168 1</ambient>
          <diffuse>0.61568627450980395466 0.81176470588235294379 0.92941176470588238168 1</diffuse>
          <specular>0.1 0.1 0.1 1</specular>
          <emissive>0 0 0 0</emissive>
        </material>
      </visual>
      <collision name="motor_subassembly_4_0_mount_tube_visual">
        <pose>0.26369959271719034533 -1.1621318268766980023e-16 0.0057470236776120337333 -0.13962634015954558664 1.9151347174783686054e-15 1.5707963267948932273</pose>
        <geometry>
          <mesh>
            <uri>model://hillstar/quad_layout_sdf//mount_tube.stl</uri>
          </mesh>
        </geometry>
      </collision>
      <visual name="motor_subassembly_4_1_motor_visual">
        <pose>0.28873464063764991971 -8.9410131687664278633e-17 0.0072458150641305230089 -0.13962634015954375477 -9.5868341907320933469e-16 1.5707963267948925612</pose>
        <geometry>
          <mesh>
            <uri>model://hillstar/quad_layout_sdf//motor.stl</uri>
          </mesh>
        </geometry>
        <material>
          <ambient>0.91764705882352937127 0.91764705882352937127 0.91764705882352937127 1</ambient>
          <diffuse>0.91764705882352937127 0.91764705882352937127 0.91764705882352937127 1</diffuse>
          <specular>0.1 0.1 0.1 1</specular>
          <emissive>0 0 0 0</emissive>
        </material>
      </visual>
      <collision name="motor_subassembly_4_1_motor_visual">
        <pose>0.28873464063764991971 -8.9410131687664278633e-17 0.0072458150641305230089 -0.13962634015954375477 -9.5868341907320933469e-16 1.5707963267948925612</pose>
        <geometry>
          <mesh>
            <uri>model://hillstar/quad_layout_sdf//motor.stl</uri>
          </mesh>
        </geometry>
      </collision>
      <visual name="motor_subassembly_4_2_mount_bottom_visual">
        <pose>0.28845629443572978756 -8.9432589347817931778e-17 0.0092263512016137402827 -0.13962634015954589195 3.0808688933347892837e-15 1.5707963267948921171</pose>
        <geometry>
          <mesh>
            <uri>model://hillstar/quad_layout_sdf//mount_bottom.stl</uri>
          </mesh>
        </geometry>
        <material>
          <ambient>0.2313725490196078538 0.38039215686274507888 0.7058823529411765163 1</ambient>
          <diffuse>0.2313725490196078538 0.38039215686274507888 0.7058823529411765163 1</diffuse>
          <specular>0.1 0.1 0.1 1</specular>
          <emissive>0 0 0 0</emissive>
        </material>
      </visual>
      <collision name="motor_subassembly_4_2_mount_bottom_visual">
        <pose>0.28845629443572978756 -8.9432589347817931778e-17 0.0092263512016137402827 -0.13962634015954589195 3.0808688933347892837e-15 1.5707963267948921171</pose>
        <geometry>
          <mesh>
            <uri>model://hillstar/quad_layout_sdf//mount_bottom.stl</uri>
          </mesh>
        </geometry>
      </collision>
      <visual name="motor_subassembly_4_3_mount_top_visual">
        <pose>0.28845629443572978756 -8.5269253005473634194e-17 0.0092263512016137472216 -0.13962634015954566991 3.1086244689504170139e-15 1.5707963267948921171</pose>
        <geometry>
          <mesh>
            <uri>model://hillstar/quad_layout_sdf//mount_top.stl</uri>
          </mesh>
        </geometry>
        <material>
          <ambient>0.64705882352941179736 0.64705882352941179736 0.64705882352941179736 1</ambient>
          <diffuse>0.64705882352941179736 0.64705882352941179736 0.64705882352941179736 1</diffuse>
          <specular>0.1 0.1 0.1 1</specular>
          <emissive>0 0 0 0</emissive>
        </material>
      </visual>
      <collision name="motor_subassembly_4_3_mount_top_visual">
        <pose>0.28845629443572978756 -8.5269253005473634194e-17 0.0092263512016137472216 -0.13962634015954566991 3.1086244689504170139e-15 1.5707963267948921171</pose>
        <geometry>
          <mesh>
            <uri>model://hillstar/quad_layout_sdf//mount_top.stl</uri>
          </mesh>
        </geometry>
      </collision>
      <inertial>
        <pose frame="motor_subassembly_4_frame">0.29810053067448266662 -7.7184183284497755173e-17 0.015751187273999784494 0 0 0</pose>
        <mass>0.11166174231785991333</mass>
        <inertia>
          <ixx>1.614878726894695854e-05</ixx>
          <ixy>3.3992971585437347816e-20</ixy>
          <ixz>-1.1832065003416435671e-06</ixz>
          <iyy>2.0082952529287425274e-05</iyy>
          <iyz>-5.4453690775056008185e-21</iyz>
          <izz>1.5934066887227334635e-05</izz>
        </inertia>
      </inertial>
    </link>
    <link name="prop_4">
      <frame name="prop_4_frame">
        <pose>0 0 0 0 -0 0</pose>
      </frame>
      <visual name="prop_4_0_prop_visual">
        <pose>0.29707697156907775238 -4.5743556096839887264e-17 0.03770325281963719799 -1.5707963267948850117 1.4311699866353524424 -1.0747854142498178663e-14</pose>
        <geometry>
          <mesh>
            <uri>model://hillstar/quad_layout_sdf//prop.stl</uri>
          </mesh>
        </geometry>
        <material>
          <ambient>0.61568627450980395466 0.81176470588235294379 0.92941176470588238168 1</ambient>
          <diffuse>0.61568627450980395466 0.81176470588235294379 0.92941176470588238168 1</diffuse>
          <specular>0.1 0.1 0.1 1</specular>
          <emissive>0 0 0 0</emissive>
        </material>
      </visual>
      <collision name="prop_4_0_prop_visual">
        <pose>0.29707697156907775238 -4.5743556096839887264e-17 0.03770325281963719799 -1.5707963267948850117 1.4311699866353524424 -1.0747854142498178663e-14</pose>
        <geometry>
          <mesh>
            <uri>model://hillstar/quad_layout_sdf//prop.stl</uri>
          </mesh>
        </geometry>
      </collision>
      <inertial>
        <pose frame="prop_4_frame">0.29728573122051787925 -4.5750691832204045754e-17 0.036217850716524793708 0 0 0</pose>
        <mass>0.024723492811985364054</mass>
        <inertia>
          <ixx>5.1936008690249114517e-06</ixx>
          <ixy>-6.3993136141418226815e-19</ixy>
          <ixz>-3.0952378850751034083e-05</ixz>
          <iyy>0.00022462477770932544265</iyy>
          <iyz>6.9817266183817767974e-19</iyz>
          <izz>0.00022108114701971850872</izz>
        </inertia>
      </inertial>
    </link>
    <joint name="rotor3" type="revolute">
      <pose>0.29707697156907775238 -4.5651707586903832896e-17 0.03770325281963719799 -1.6408531037040997955e-15 0.13962634015953998001 3.1415926535897868987</pose>
      <parent>motor_subassembly_4</parent>
      <child>prop_4</child>
      <axis>
        <xyz>0 0 1</xyz>
        <limit>
          <effort>1</effort>
          <velocity>20</velocity>
        </limit>
      </axis>
    </joint>
    <joint name="tilt3" type="revolute">
      <pose>0.26369959271719034533 -1.1621318268766980023e-16 0.0057470236776120337333 -1.7104226669544422279 1.9151347174783686054e-15 1.5707963267948932273</pose>
      <parent>quad_plate_arm_subassembly</parent>
      <child>motor_subassembly_4</child>
      <axis>
        <xyz>0 0 1</xyz>
        <limit>
          <effort>1</effort>
          <velocity>20</velocity>
        </limit>
      </axis>
    </joint>


    <plugin filename="gz-sim-multicopter-motor-model-system" name="gz::sim::systems::MulticopterMotorModel">
      <jointName>rotor0</jointName>
      <linkName>prop</linkName>
      <turningDirection>cw</turningDirection>
      <timeConstantUp>0.0125</timeConstantUp>
      <timeConstantDown>0.025</timeConstantDown>
      <maxRotVelocity>1000.0</maxRotVelocity>
      <motorConstant>8.54858e-06</motorConstant>
      <momentConstant>0.016</momentConstant>
      <commandSubTopic>command/motor_speed</commandSubTopic>
      <motorNumber>0</motorNumber>
      <rotorDragCoefficient>8.06428e-05</rotorDragCoefficient>
      <rollingMomentCoefficient>1e-06</rollingMomentCoefficient>
      <rotorVelocitySlowdownSim>10</rotorVelocitySlowdownSim>
      <motorType>velocity</motorType>
    </plugin>

        <plugin filename="gz-sim-multicopter-motor-model-system" name="gz::sim::systems::MulticopterMotorModel">
      <jointName>rotor1</jointName>
      <linkName>prop_2</linkName>
      <turningDirection>cw</turningDirection>
      <timeConstantUp>0.0125</timeConstantUp>
      <timeConstantDown>0.025</timeConstantDown>
      <maxRotVelocity>1000.0</maxRotVelocity>
      <motorConstant>8.54858e-06</motorConstant>
      <momentConstant>0.016</momentConstant>
      <commandSubTopic>command/motor_speed</commandSubTopic>
      <motorNumber>1</motorNumber>
      <rotorDragCoefficient>8.06428e-05</rotorDragCoefficient>
      <rollingMomentCoefficient>1e-06</rollingMomentCoefficient>
      <rotorVelocitySlowdownSim>10</rotorVelocitySlowdownSim>
      <motorType>velocity</motorType>
    </plugin>

    <plugin filename="gz-sim-multicopter-motor-model-system" name="gz::sim::systems::MulticopterMotorModel">
      <jointName>rotor2</jointName>
      <linkName>prop_3</linkName>
      <turningDirection>cw</turningDirection>
      <timeConstantUp>0.0125</timeConstantUp>
      <timeConstantDown>0.025</timeConstantDown>
      <maxRotVelocity>1000.0</maxRotVelocity>
      <motorConstant>8.54858e-06</motorConstant>
      <momentConstant>0.016</momentConstant>
      <commandSubTopic>command/motor_speed</commandSubTopic>
      <motorNumber>2</motorNumber>
      <rotorDragCoefficient>8.06428e-05</rotorDragCoefficient>
      <rollingMomentCoefficient>1e-06</rollingMomentCoefficient>
      <rotorVelocitySlowdownSim>10</rotorVelocitySlowdownSim>
      <motorType>velocity</motorType>
    </plugin>

        <plugin filename="gz-sim-multicopter-motor-model-system" name="gz::sim::systems::MulticopterMotorModel">
      <jointName>rotor3</jointName>
      <linkName>prop_4</linkName>
      <turningDirection>cw</turningDirection>
      <timeConstantUp>0.0125</timeConstantUp>
      <timeConstantDown>0.025</timeConstantDown>
      <maxRotVelocity>1000.0</maxRotVelocity>
      <motorConstant>8.54858e-06</motorConstant>
      <momentConstant>0.016</momentConstant>
      <commandSubTopic>command/motor_speed</commandSubTopic>
      <motorNumber>3</motorNumber>
      <rotorDragCoefficient>8.06428e-05</rotorDragCoefficient>
      <rollingMomentCoefficient>1e-06</rollingMomentCoefficient>
      <rotorVelocitySlowdownSim>10</rotorVelocitySlowdownSim>
      <motorType>velocity</motorType>
    </plugin>



  </model>
</sdf>
